<?xml version="1.0" encoding="UTF-8"?>
<testng-results ignored="0" total="5" passed="4" failed="1" skipped="0">
  <reporter-output>
  </reporter-output>
  <suite started-at="2022-11-21T13:22:03 IST" name="Default suite" finished-at="2022-11-21T13:22:58 IST" duration-ms="54431">
    <groups>
    </groups>
    <test started-at="2022-11-21T13:22:03 IST" name="Default test" finished-at="2022-11-21T13:22:58 IST" duration-ms="54431">
      <class name="tests.myDetails.MyException">
        <test-method is-config="true" signature="initialize()[pri:0, instance:tests.myDetails.MyException@7db12bb6]" started-at="2022-11-21T13:22:03 IST" name="initialize" finished-at="2022-11-21T13:22:23 IST" duration-ms="19802" status="PASS">
          <reporter-output>
          </reporter-output>
        </test-method> <!-- initialize -->
        <test-method signature="validateMyExceptionPage()[pri:0, instance:tests.myDetails.MyException@7db12bb6]" started-at="2022-11-21T13:22:23 IST" name="validateMyExceptionPage" finished-at="2022-11-21T13:22:37 IST" duration-ms="14286" status="PASS">
          <reporter-output>
          </reporter-output>
        </test-method> <!-- validateMyExceptionPage -->
        <test-method signature="validateMyExceptionList()[pri:1, instance:tests.myDetails.MyException@7db12bb6]" started-at="2022-11-21T13:22:37 IST" name="validateMyExceptionList" finished-at="2022-11-21T13:22:40 IST" duration-ms="2905" status="PASS">
          <reporter-output>
          </reporter-output>
        </test-method> <!-- validateMyExceptionList -->
        <test-method signature="validateIconCount()[pri:2, instance:tests.myDetails.MyException@7db12bb6]" started-at="2022-11-21T13:22:40 IST" name="validateIconCount" finished-at="2022-11-21T13:22:40 IST" duration-ms="144" status="PASS">
          <reporter-output>
          </reporter-output>
        </test-method> <!-- validateIconCount -->
        <test-method signature="validateException()[pri:3, instance:tests.myDetails.MyException@7db12bb6]" started-at="2022-11-21T13:22:40 IST" name="validateException" finished-at="2022-11-21T13:22:45 IST" duration-ms="4694" status="PASS">
          <reporter-output>
          </reporter-output>
        </test-method> <!-- validateException -->
        <test-method signature="validateHPUAStatus()[pri:4, instance:tests.myDetails.MyException@7db12bb6]" started-at="2022-11-21T13:22:45 IST" name="validateHPUAStatus" finished-at="2022-11-21T13:22:58 IST" duration-ms="12533" status="FAIL">
          <exception class="java.lang.AssertionError">
            <message>
              <![CDATA[expected [true] but found [false]]]>
            </message>
            <full-stacktrace>
              <![CDATA[java.lang.AssertionError: expected [true] but found [false]
at org.testng.Assert.fail(Assert.java:99)
at org.testng.Assert.failNotEquals(Assert.java:1037)
at org.testng.Assert.assertTrue(Assert.java:45)
at org.testng.Assert.assertTrue(Assert.java:55)
at tests.myDetails.MyException.validateHPUAStatus(MyException.java:167)
at java.base/jdk.internal.reflect.NativeMethodAccessorImpl.invoke0(Native Method)
at java.base/jdk.internal.reflect.NativeMethodAccessorImpl.invoke(NativeMethodAccessorImpl.java:77)
at java.base/jdk.internal.reflect.DelegatingMethodAccessorImpl.invoke(DelegatingMethodAccessorImpl.java:43)
at java.base/java.lang.reflect.Method.invoke(Method.java:568)
at org.testng.internal.MethodInvocationHelper.invokeMethod(MethodInvocationHelper.java:133)
at org.testng.internal.TestInvoker.invokeMethod(TestInvoker.java:598)
at org.testng.internal.TestInvoker.invokeTestMethod(TestInvoker.java:173)
at org.testng.internal.MethodRunner.runInSequence(MethodRunner.java:46)
at org.testng.internal.TestInvoker$MethodInvocationAgent.invoke(TestInvoker.java:824)
at org.testng.internal.TestInvoker.invokeTestMethods(TestInvoker.java:146)
at org.testng.internal.TestMethodWorker.invokeTestMethods(TestMethodWorker.java:146)
at org.testng.internal.TestMethodWorker.run(TestMethodWorker.java:128)
at java.base/java.util.ArrayList.forEach(ArrayList.java:1511)
at org.testng.TestRunner.privateRun(TestRunner.java:794)
at org.testng.TestRunner.run(TestRunner.java:596)
at org.testng.SuiteRunner.runTest(SuiteRunner.java:377)
at org.testng.SuiteRunner.runSequentially(SuiteRunner.java:371)
at org.testng.SuiteRunner.privateRun(SuiteRunner.java:332)
at org.testng.SuiteRunner.run(SuiteRunner.java:276)
at org.testng.SuiteRunnerWorker.runSuite(SuiteRunnerWorker.java:53)
at org.testng.SuiteRunnerWorker.run(SuiteRunnerWorker.java:96)
at org.testng.TestNG.runSuitesSequentially(TestNG.java:1212)
at org.testng.TestNG.runSuitesLocally(TestNG.java:1134)
at org.testng.TestNG.runSuites(TestNG.java:1063)
at org.testng.TestNG.run(TestNG.java:1031)
at org.testng.remote.AbstractRemoteTestNG.run(AbstractRemoteTestNG.java:115)
at org.testng.remote.RemoteTestNG.initAndRun(RemoteTestNG.java:251)
at org.testng.remote.RemoteTestNG.main(RemoteTestNG.java:77)
]]>
            </full-stacktrace>
          </exception> <!-- java.lang.AssertionError -->
          <reporter-output>
          </reporter-output>
        </test-method> <!-- validateHPUAStatus -->
      </class> <!-- tests.myDetails.MyException -->
    </test> <!-- Default test -->
  </suite> <!-- Default suite -->
</testng-results>
